File: opendata/20240530_VCl3_HC_pulses.raw
[Header]
TITLE,
BYAPP,HeatCapacity,3.9.6,4.0
INFO,PPMS Heat Capacity Option 3.9.6 Build 3,APPNAME
DATATYPE,TIME,1
DATATYPE,COMMENT,2
STARTUPAXIS, X, 1, LINEAR, AUTO
STARTUPAXIS, Y1, 4, LINEAR, AUTO
[Data]
Time Stamp (Seconds),Comment (),Therm Res (Ohms),Platform Temp (Kelvin),Heater Power (Watts),Platform Temp Fit (Kelvin),Sample Temp Fit (Kelvin)
5303068.84,CALFILE: C:\QdPpms\HEATCA~3\TempCal\Standard\Puck921.cal|Addenda #0 measured on 20/12/2009 from 1.879 to 397.11 K
5303069.13,BEGIN:PULSE:PARAMS
5303069.13,ThResSigmaPerCycle=1.41185209070117
5303069.13,TempSigmaPerCycle=0.0308427628627204
5303069.13,NBinsOn=128
5303069.13,NBinsOff=128
5303069.13,Period=42.690592
5303069.13,Iterations=1
5303069.13,HtrOverLoad=0
5303069.13,NCycRec=40
5303069.13,ThFreqHz=244.140625
5303069.13,NSampPerBin=40
5303069.13,PPMSTemp=15.0014
5303069.13,EstTau=6.098656
5303069.13,ThermOverload=0
5303069.13,ThResCorrFact=1
5303069.13,AvgHtrOnResistance=1191.21204299412
5303069.13,IsAddenda=0
5303069.13,AddendafromTbl=5.69374953616585E-5
5303069.13,AddendafromTblMinMidMax=1.93045749237883E-5|5.38045509142104E-5|0.000104252953117412
5303069.13,AddendaOffsetMinMidMax=0|0|0
5303069.13,AddendaErrfromTbl=2.15370052706754E-7
5303069.13,CondfromTbl=2.2302856968777E-5
5303069.13,TempMinMidMax=15.107509554484|22.1462429820516|29.1849764096192
5303069.13,CondfromTblMinMidMax=1.77541188191821E-5|2.62349908212165E-5|3.35009272883691E-5
5303069.13,DisableTau2Fitting=1
5303069.13,HtrCurrOn=0.000537298165646474
5303069.13,StableStartTemperature=15.0843838043001
5303069.13,TimeStamp=5303069.13
5303069.13,PPMSStatus=5905
5303069.13,PuckTemp=
5303069.13,SystemTemp=15.003
5303069.13,Field=-0.178
5303069.13,Pressure=0.0001151
5303069.13,SampleTemp=22.552594
5303069.13,TempRise=13.927359
5303069.13,SampHC=6527.3733
5303069.13,SampHCErr=821
5303069.13,AddendaHC=56.937495
5303069.13,AddendaHCErr=0.2154
5303069.13,TotalHC=106.7331
5303069.13,TotalHCErr=4.687
5303069.13,FitDeviation=15700.92
5303069.13,TimeConsttau1=4.3912551
5303069.13,TimeConsttau2=
5303069.13,SampleCoupling=
5303069.13,DebyeTemp=237.5362
5303069.13,DebyeTempErr=14.36
5303069.13,CalCorrection=1
5303069.13,ThermCondWire=2.4305829E-5
5303069.13,AddendaOffset=0
5303069.13,END:PULSE:PARAMS
5303069.297936,,812.792544498678,15.7894898099529,0.000348981368964134,15.8624319632246,15.8624319632246
5303069.465872,,766.128487638622,16.8811677287366,0.000348168496658057,16.3828020415052,16.3828020415052
5303069.633808,,733.228249103356,17.7455003761737,0.000347588672604869,16.8836471892266,16.8836471892266
5303069.801744,,708.117009027012,18.4649401140967,0.000347137491187276,17.365700005993,17.365700005993
5303069.96968,,688.069897896137,19.0811651272944,0.000346790715386977,17.829665603363,17.829665603363
5303070.137616,,671.5929696907,19.6178840115323,0.000346501735553395,18.2762226362351,18.2762226362351
5303070.305552,,657.752902814311,20.0912459842165,0.000346250043440275,18.7060242955348,18.7060242955348
5303070.473488,,645.93137123671,20.5131198728748,0.000346044960977732,19.119699263654,19.119699263654
5303070.641424,,635.696085562332,20.8922903052471,0.000345854793603375,19.5178526340416,19.5178526340416
5303070.80936,,626.717473574101,21.2360483930373,0.000345716829037665,19.9010667962903,19.9010667962903
5303070.977296,,618.737106942781,21.550703276813,0.0003455583562257,20.2699022880131,20.2699022880131
5303071.145232,,611.462582965911,21.8452905701348,0.000345429713590106,20.6248986147564,20.6248986147564
5303071.313168,,604.495359747208,22.1346218020393,0.000345304799726557,20.9665750391501,20.9665750391501
5303071.481104,,597.611172392284,22.4276484238902,0.000345174292704939,21.295431340446,21.295431340446
5303071.64904,,590.974769197355,22.7170742026747,0.000345066158315599,21.6119485455587,21.6119485455587
5303071.816976,,584.727303568379,22.9959705945304,0.000344952430768189,21.9165896326766,21.9165896326766
5303071.984912,,578.90619080008,23.2616906276909,0.000344849889536918,22.2098002084725,22.2098002084725
5303072.152848,,573.482712432284,23.5145520438953,0.000344762263393831,22.4920091599042,22.4920091599042
5303072.320784,,568.43019187032,23.7548233006251,0.00034466531532063,22.763629281559,22.763629281559
5303072.48872,,563.72416454048,23.9827920613181,0.000344579553563567,23.0250578794597,23.0250578794597
5303072.656656,,559.327933582199,24.1994682998475,0.000344508706894688,23.2766773522142,23.2766773522142
5303072.824592,,555.223273455249,24.4050767981381,0.000344441588997856,23.5188557503605,23.5188557503605
5303072.992528,,551.37305245734,24.600892517623,0.000344367013556932,23.7519473147244,23.7519473147244
5303073.160464,,547.764319867457,24.7870659337044,0.000344311081976238,23.9762929945763,23.9762929945763
5303073.3284,,544.372856891999,24.9643959239161,0.000344249557237476,24.1922209463474,24.1922209463474
5303073.496336,,541.185996402384,25.1331621963125,0.000344180574954621,24.4000470136327,24.4000470136327
5303073.664272,,538.185323796763,25.2940154876263,0.000344128372145974,24.6000751891838,24.6000751891838
5303073.832208,,535.349758704435,25.4477834930566,0.000344087355653465,24.7925980595675,24.7925980595675
5303074.000144,,532.680019559559,25.594152037271,0.000344044474774934,24.9778972331396,24.9778972331396
5303074.16808,,530.150204920109,25.7342965198205,0.000343996000738333,25.1562437519615,25.1562437519615
5303074.336016,,527.753603098554,25.8683791620205,0.00034395871301787,25.3278984882601,25.3278984882601
5303074.503952,,525.488644883441,25.9962912881496,0.000343915832139339,25.4931125260131,25.4931125260131
5303074.671888,,523.339165506206,26.1187693175109,0.000343887866348992,25.6521275282159,25.6521275282159
5303074.839824,,521.29680844322,26.2361368114574,0.000343852443014553,25.8051760903686,25.8051760903686
5303075.00776,,519.357546681961,26.3484861973403,0.000343818884066137,25.9524820807001,25.9524820807001
5303075.175696,,517.517920394773,26.4558885290216,0.000343779731959652,26.0942609676253,26.0942609676253
5303075.343632,,515.767115256955,26.5588594405215,0.000343757359327374,26.2307201349173,26.2307201349173
5303075.511568,,514.094562723915,26.6579220119713,0.000343723800378958,26.3620591850527,26.3620591850527
5303075.679504,,512.507636198857,26.7525461144173,0.000343699563360658,26.488470231176,26.488470231176
5303075.84744,,510.987732018312,26.8437571274088,0.000343679055114404,26.610138178108,26.610138178108
5303076.015376,,509.535757678057,26.9314293423837,0.000343645496165988,26.7272409928115,26.7272409928115
5303076.183312,,508.15515409959,27.0152835848854,0.000343617530375641,26.839949964708,26.839949964708
5303076.351248,,506.831930722982,27.0961060220868,0.00034359888651541,26.9484299562279,26.9484299562279
5303076.519184,,505.573026109712,27.1734149494442,0.000343572785111086,27.0528396439585,27.0528396439585
5303076.68712,,504.367134374866,27.2478507355213,0.000343550412478809,27.1533317507448,27.1533317507448
5303076.855056,,503.210909127759,27.3195746217543,0.000343531768618578,27.2500532690813,27.2500532690813
5303077.022992,,502.104728491632,27.3885205684798,0.000343518717916416,27.343145676122,27.343145676122
5303077.190928,,501.043676864348,27.4549556667243,0.000343492616512092,27.4327451406226,27.4327451406226
5303077.358864,,500.034314684144,27.5184304954541,0.000343483294581977,27.5189827221181,27.5189827221181
5303077.5268,,499.057622351984,27.5801087084076,0.000343460921949699,27.6019845626275,27.6019845626275
5303077.694736,,498.129159639246,27.638977724176,0.000343444142475492,27.6818720711645,27.6818720711645
5303077.862672,,497.23022835165,27.6961951712397,0.000343432956159353,27.7587621013263,27.7587621013263
5303078.030608,,496.370735318117,27.751106648232,0.000343438549317422,27.8327671222183,27.8327671222183
5303078.198544,,495.547995863634,27.8038580553891,0.000343414312299122,27.9039953829654,27.9039953829654
5303078.36648,,494.7550336144,27.8548751826866,0.000343390075280821,27.9725510710513,27.9725510710513
5303078.534416,,493.9924535676,27.904100341773,0.000343382617736729,28.038534464716,28.038534464716
5303078.702352,,493.260369160208,27.9515077925769,0.000343365838262521,28.1020420796357,28.1020420796357
5303078.870288,,492.558440081306,27.9971018228676,0.000343367702648544,28.1631668100986,28.1631668100986
5303079.038224,,491.882771661508,28.041120154001,0.000343349058788313,28.2219980648842,28.2219980648842
5303079.20616,,491.231303129151,28.0836842056988,0.000343332279314105,28.2786218980437,28.2786218980437
5303079.374096,,490.604374795152,28.124758684638,0.000343334143700128,28.3331211347735,28.3331211347735
5303079.542032,,490.003763838743,28.1642139652805,0.00034331736422592,28.385575492566,28.385575492566
5303079.709968,,489.425802464486,28.2022787315276,0.000343315499839897,28.4360616978145,28.4360616978145
5303079.877904,,488.869356302657,28.2390170384193,0.000343298720365689,28.4846535980427,28.4846535980427
5303080.04584,,488.329131627876,28.2747696022479,0.000343298720365689,28.5314222699238,28.5314222699238
5303080.213776,,487.810781382603,28.3091536971676,0.000343280076505458,28.5764361232461,28.5764361232461
5303080.381712,,487.310902457665,28.3423862078506,0.000343278212119434,28.6197610009777,28.6197610009777
5303080.549648,,486.830629222786,28.3743836555735,0.000343274483347388,28.6614602755771,28.6614602755771
5303080.717584,,486.368865120566,28.4052112922522,0.000343252110715111,28.7015949416894,28.7015949416894
5303080.88552,,485.923454848531,28.4350061216182,0.000343248381943065,28.740223705365,28.740223705365
5303081.053456,,485.489690772326,28.4640777139658,0.00034323346685488,28.7774030699305,28.7774030699305
5303081.221392,,485.074322391808,28.4919681432498,0.000343229738082834,28.8131874186378,28.8131874186378
5303081.389328,,484.675440184609,28.5187993540608,0.000343229738082834,28.8476290942115,28.8476290942115
5303081.557264,,484.292363528894,28.5446115443512,0.00034322787369681,28.8807784754124,28.8807784754124
5303081.7252,,483.917435429028,28.5699166604727,0.000343218551766695,28.9126840507279,28.9126840507279
5303081.893136,,483.559503968857,28.5941134542266,0.000343220416152718,28.9433924892968,28.9433924892968
5303082.061072,,483.217321341684,28.6172811411085,0.000343207365450556,28.9729487091743,28.9729487091743
5303082.229008,,482.880394627564,28.6401269869189,0.00034320363667851,29.0013959430344,29.0013959430344
5303082.396944,,482.55717488094,28.6620751903918,0.000343192450362371,29.0287758014075,29.0287758014075
5303082.56488,,482.242519625731,28.6834717734391,0.000343190585976348,29.0551283335454,29.0551283335454
5303082.732816,,481.946430221666,28.7036329102782,0.000343183128432256,29.0804920860021,29.0804920860021
5303082.900752,,481.652949867967,28.7236423043697,0.000343175670888163,29.1049041590175,29.1049041590175
5303083.068688,,481.372136642849,28.7428122486904,0.000343181264046233,29.128400260784,29.128400260784
5303083.236624,,481.102988519725,28.7612081050672,0.000343170077730094,29.1510147596788,29.1510147596788
5303083.40456,,480.837980846092,28.7793422699432,0.00034317939966021,29.1727807345347,29.1727807345347
5303083.572496,,480.58719060633,28.796523048122,0.000343164484572025,29.1937300230257,29.1937300230257
5303083.740432,,480.342525963076,28.8133024789069,0.000343162620186002,29.2138932682369,29.2138932682369
5303083.908368,,480.105896438699,28.8295480642994,0.000343145840711794,29.2332999634868,29.2332999634868
5303084.076304,,479.879854365077,28.8450826069102,0.000343157027027932,29.251978495468,29.251978495468
5303084.24424,,479.658973673699,28.8602773989281,0.000343147705097817,29.2699561857691,29.2699561857691
5303084.412176,,479.446581849086,28.8749021903553,0.000343140247553724,29.2872593308392,29.2872593308392
5303084.580112,,479.238727503369,28.8892278133995,0.00034314956948384,29.3039132404515,29.3039132404515
5303084.748048,,479.040704361924,28.9028880816887,0.000343134654395655,29.3199422747255,29.3199422747255
5303084.915984,,478.848995878608,28.9161241232367,0.000343130925623609,29.3353698797586,29.3353698797586
5303085.08392,,478.662637839156,28.9290014983865,0.000343132790009632,29.3502186219218,29.3502186219218
5303085.251856,,478.483501953612,28.9413898143212,0.000343132790009632,29.3645102208676,29.3645102208676
5303085.419792,,478.305613874764,28.9537015405634,0.000343127196851562,29.3782655813005,29.3782655813005
5303085.587728,,478.13712215846,28.9653718657664,0.00034314397632577,29.3915048235542,29.3915048235542
5303085.755664,,477.974548070883,28.9766405552514,0.000343127196851562,29.4042473130228,29.4042473130228
5303085.9236,,477.820595193207,28.9873191399622,0.000343121603693493,29.4165116884868,29.4165116884868
5303086.091536,,477.665753725913,28.9980666932648,0.000343123468079516,29.4283158893764,29.4283158893764
5303086.259472,,477.520440964299,29.0081595543229,0.000343116010535424,29.4396771820122,29.4396771820122
5303086.427408,,477.376773038784,29.0181445503551,0.000343104824219285,29.4506121848612,29.4506121848612
5303086.595344,,477.239760082316,29.0276729361428,0.000343106688605308,29.4611368928446,29.4611368928446
5303086.76328,,477.108078663549,29.0368359922685,0.000343101095447239,29.4712667007346,29.4712667007346
5303086.931216,,476.977815206937,29.0459056346823,0.000343106688605308,29.4810164256723,29.4810164256723
5303087.099152,,476.853904220778,29.0545378382358,0.000343097366675193,29.4904003288414,29.4904003288414
5303087.267088,,476.733774467031,29.0629111457346,0.000343106688605308,29.4994321363283,29.4994321363283
5303087.435024,,476.614003930364,29.0712638499474,0.000343093637903146,29.5081250591994,29.5081250591994
5303087.60296,,476.504026785645,29.0789374732157,0.000343088044745077,29.5164918128257,29.5164918128257
5303087.770896,,476.392877458879,29.0866966838525,0.0003430899091311,29.5245446354819,29.5245446354819
5303087.938832,,476.284979991987,29.0942325409956,0.000343086180359054,29.532295306247,29.532295306247
5303088.106768,,476.1833593709,29.1013333007657,0.000343086180359054,29.5397551622348,29.5397551622348
5303088.274704,,476.082910931861,29.1083552970654,0.000343088044745077,29.5469351151762,29.5469351151762
5303088.44264,,475.987907467495,29.114999531292,0.000343093637903146,29.5538456673806,29.5538456673806
5303088.610576,,475.897989760725,29.1212906617499,0.000343078722814962,29.5604969270977,29.5604969270977
5303088.778512,,475.809735796216,29.12746782666,0.000343074994042915,29.5668986233031,29.5668986233031
5303088.946448,,475.719742464798,29.1337692244829,0.000343078722814962,29.5730601199293,29.5730601199293
5303089.114384,,475.635742386753,29.13965323962,0.000343076858428938,29.5789904295622,29.5789904295622
5303089.28232,,475.550910437578,29.145597750282,0.000343082451587008,29.5846982266245,29.5846982266245
5303089.450256,,475.473281736148,29.1510394608745,0.000343078722814962,29.5901918600638,29.5901918600638
5303089.618192,,475.400776604638,29.1561237057993,0.000343076858428938,29.5954793655647,29.5954793655647
5303089.786128,,475.327534132807,29.1612613154255,0.000343071265270869,29.6005684773031,29.6005684773031
5303089.954064,,475.250718396346,29.1666513663113,0.000343076858428938,29.6054666392589,29.6054666392589
5303090.122,,475.184338861344,29.1713106036249,0.000343073129656892,29.6101810161048,29.6101810161048
5303090.289936,,475.116976205914,29.1760402502006,0.000343073129656892,29.6147185036859,29.6147185036859
5303090.457872,,475.054623683432,29.1804193870146,0.000343069400884846,29.6190857391068,29.6190857391068
5303090.625808,,474.989756641394,29.1849764096192,0.000343073129656892,29.6232891104397,29.6232891104397
5303090.793744,,477.956889715517,28.9778650172324,0,29.3538169634757,29.3538169634757
5303090.96168,,483.23836390006,28.6158554377888,0,28.8373407428082,28.8373407428082
5303091.129616,,488.410409218584,28.2693851988531,0,28.3402433503341,28.3402433503341
5303091.297552,,493.570638185819,27.9313976795486,0,27.8617976683911,27.8617976683911
5303091.465488,,498.761684197216,27.5988475238573,0,27.4013038616735,27.4013038616735
5303091.633424,,503.986402083247,27.2714302512209,0,26.9580883535636,26.9580883535636
5303091.80136,,509.25375336473,26.9485184765174,0,26.5315028408738,26.5315028408738
5303091.969296,,514.569825825848,26.6297035897774,0,26.120923345556,26.120923345556
5303092.137232,,519.926054975187,26.3154580993722,0,25.725749301992,25.725749301992
5303092.305168,,525.320663633513,26.005824589353,0,25.3454026785304,25.3454026785304
5303092.473104,,530.751647747648,25.7008495929648,0,24.9793271319839,24.9793271319839
5303092.64104,,536.221162620067,25.400344417873,0,24.6269871938516,24.6269871938516
5303092.808976,,541.718582987691,25.1048108744933,0,24.2878674870746,24.2878674870746
5303092.976912,,547.240051993458,24.8143277321785,0,23.9614719721803,23.9614719721803
5303093.144848,,552.779746539454,24.5290158835543,0,23.6473232217122,23.6473232217122
5303093.312784,,558.338990057023,24.2487119621139,0,23.3449617218838,23.3449617218838
5303093.48072,,563.90509651142,23.9739518901351,0,23.0539452004358,23.0539452004358
5303093.648656,,569.470560156307,23.7049726192027,0,22.7738479797125,22.7738479797125
5303093.816592,,575.03296100294,23.4417454989676,0,22.5042603540114,22.5042603540114
5303093.984528,,580.579026925551,23.1847336720512,0,22.2447879902962,22.2447879902962
5303094.152464,,586.096090795558,22.9343221261038,0,21.9950513513949,21.9950513513949
5303094.3204,,591.55949897763,22.6912933793085,0,21.754685140841,21.754685140841
5303094.488336,,596.934483039736,22.4568440996723,0,21.5233377685441,21.5233377685441
5303094.656272,,602.166687765944,22.2329355749463,0,21.3006708365102,21.3006708365102
5303094.824208,,607.187502694128,22.0219747834252,0,21.0863586438574,21.0863586438574
5303094.992144,,611.943612447273,21.8255769707184,0,20.8800877104049,20.8800877104049
5303095.16008,,616.506425599488,21.6402366786117,0,20.6815563181368,20.6815563181368
5303095.328016,,621.003104996808,21.460465805824,0,20.4904740698716,20.4904740698716
5303095.495952,,625.517253687874,21.2828145940309,0,20.3065614644897,20.3065614644897
5303095.663888,,630.069687357117,21.1064563212909,0,20.1295494881003,20.1295494881003
5303095.831824,,634.682053560098,20.9305832141713,0,19.9591792205474,19.9591792205474
5303095.99976,,639.347791858583,20.7554886854032,0,19.7952014566802,19.7952014566802
5303096.167696,,644.064104140585,20.5813110590806,0,19.637376341834,19.637376341834
5303096.335632,,648.830423221244,20.4081002448866,0,19.4854730209889,19.4854730209889
5303096.503568,,653.623305459601,20.2367149490687,0,19.3392693010912,19.3392693010912
5303096.671504,,658.463169510683,20.0664283073158,0,19.1985513260464,19.1985513260464
5303096.83944,,663.328084226498,19.8980003328831,0,19.0631132639055,19.0631132639055
5303097.007376,,668.215270401224,19.7314592939378,0,18.9327570057898,18.9327570057898
5303097.175312,,673.116655103658,19.5670532159359,0,18.8072918761111,18.8072918761111
5303097.343248,,678.016508406965,19.4052693700559,0,18.6865343536659,18.6865343536659
5303097.511184,,682.922581837591,19.2458059291201,0,18.5703078031936,18.5703078031936
5303097.67912,,687.823890915377,19.088972575973,0,18.4584422170076,18.4584422170076
5303097.847056,,692.706331643425,18.9351556589501,0,18.3507739663208,18.3507739663208
5303098.014992,,697.573326037067,18.7841763400857,0,18.2471455619008,18.2471455619008
5303098.182928,,702.406213714349,18.6365337665055,0,18.1474054237065,18.1474054237065
5303098.350864,,707.203274214521,18.492189111547,0,18.0514076591679,18.0514076591679
5303098.5188,,711.969082828803,18.3509182705105,0,17.9590118497853,17.9590118497853
5303098.686736,,716.677794833657,18.2133899683975,0,17.8700828457349,17.8700828457349
5303098.854672,,721.332359590362,18.079409515435,0,17.7844905681822,17.7844905681822
5303099.022608,,725.931321324442,17.9489095631125,0,17.7021098190116,17.7021098190116
5303099.190544,,730.454960908863,17.8222891886745,0,17.6228200976962,17.6228200976962
5303099.35848,,734.916191252316,17.6990723116955,0,17.5465054250383,17.5465054250383
5303099.526416,,739.296011661926,17.5796825142291,0,17.4730541735232,17.4730541735232
5303099.694352,,743.598184463945,17.4639115599858,0,17.4023589040393,17.4023589040393
5303099.862288,,747.81380485604,17.3518947902916,0,17.3343162087236,17.3343162087236
5303100.030224,,751.93304163394,17.243783963518,0,17.2688265597042,17.2688265597042
5303100.19816,,755.962719922149,17.1392934692995,0,17.2057941635186,17.2057941635186
5303100.366096,,759.891855240508,17.0386042200411,0,17.1451268209936,17.1451268209936
5303100.534032,,763.724058665972,16.9415208546902,0,17.0867357923833,17.0867357923833
5303100.701968,,767.446719788445,16.8482607209241,0,17.0305356675672,17.0305356675672
5303100.869904,,771.063506403366,16.7586307155877,0,16.9764442411184,16.9764442411184
5303101.03784,,774.573586639605,16.6725560510388,0,16.9243823920595,16.9243823920595
5303101.205776,,777.974238009826,16.5900111948544,0,16.8742739681303,16.8742739681303
5303101.373712,,781.258540858712,16.5110727564845,0,16.8260456743978,16.8260456743978
5303101.541648,,784.437252792478,16.4353881580915,0,16.7796269660459,16.7796269660459
5303101.709584,,787.498406210538,16.363147704921,0,16.7349499451872,16.7349499451872
5303101.87752,,790.450055137931,16.2940836016347,0,16.6919492615474,16.6919492615474
5303102.045456,,793.290422395423,16.2281659922575,0,16.6505620168757,16.6505620168757
5303102.213392,,796.019621419986,16.1653242603306,0,16.6107276729412,16.6107276729412
5303102.381328,,798.643116092456,16.1053698401169,0,16.572387962983,16.572387962983
5303102.549264,,801.154932065622,16.0483799025286,0,16.5354868064809,16.5354868064809
5303102.7172,,803.56365273706,15.99410428735,0,16.4999702271256,16.4999702271256
5303102.885136,,805.867103898133,15.942541192727,0,16.4657862738658,16.4657862738658
5303103.053072,,808.065342267327,15.8936410142369,0,16.4328849449179,16.4328849449179
5303103.221008,,810.169276700152,15.847117758736,0,16.4012181146275,16.4012181146275
5303103.388944,,812.173708002041,15.8030466892994,0,16.3707394630742,16.3707394630742
5303103.55688,,814.083929898371,15.7612740191985,0,16.3414044083185,16.3414044083185
5303103.724816,,815.904177369445,15.7216735871757,0,16.3131700411907,16.3131700411907
5303103.892752,,817.631973708032,15.6842679997304,0,16.2859950625261,16.2859950625261
5303104.060688,,819.279437764015,15.6487669377439,0,16.2598397227561,16.2598397227561
5303104.228624,,820.842901741953,15.6152243797225,0,16.234665763765,16.234665763765
5303104.39656,,822.323065169843,15.583601341116,0,16.2104363629292,16.2104363629292
5303104.564496,,823.730364249143,15.5536537699678,0,16.1871160792555,16.1871160792555
5303104.732432,,825.062038680193,15.5254215385736,0,16.1646708015407,16.1646708015407
5303104.900368,,826.323325469882,15.4987761676998,0,16.1430676984764,16.1430676984764
5303105.068304,,827.516776950091,15.4736482009857,0,16.1222751706253,16.1222751706253
5303105.23624,,828.641466718878,15.4500427340801,0,16.1022628042005,16.1022628042005
5303105.404176,,829.71405110502,15.427598146591,0,16.0830013265778,16.0830013265778
5303105.572112,,830.720047988377,15.4066063986518,0,16.0644625634784,16.0644625634784
5303105.740048,,831.674525580113,15.3867426841426,0,16.0466193977573,16.0466193977573
5303105.907984,,832.573456867709,15.3680819719898,0,16.0294457297382,16.0294457297382
5303106.07592,,833.418562311912,15.3505800791328,0,16.0129164390374,16.0129164390374
5303106.243856,,834.216629224903,15.3340891140366,0,15.9970073478189,15.9970073478189
5303106.411792,,834.973858827839,15.3184749242651,0,15.981695185429,15.981695185429
5303106.579728,,835.680419916447,15.3039343635225,0,15.9669575543579,15.9669575543579
5303106.747664,,836.347561657154,15.2902305120508,0,15.9527728974783,15.9527728974783
5303106.9156,,836.979726998045,15.2772679005724,0,15.9391204665127,15.9391204665127
5303107.083536,,837.568767383271,15.2652094786131,0,15.9259802916851,15.9259802916851
5303107.251472,,838.129259463782,15.2537532700387,0,15.9133331525098,15.9133331525098
5303107.419408,,838.654132334967,15.2430408016594,0,15.901160549678,15.901160549678
5303107.587344,,839.148868783824,15.232957281491,0,15.8894446779976,15.8894446779976
5303107.75528,,839.612788188519,15.223514072288,0,15.8781684003495,15.8781684003495
5303107.923216,,840.049444907519,15.2146365807047,0,15.8673152226205,15.8673152226205
5303108.091152,,840.460445964601,15.2062902173575,0,15.8568692695771,15.8568692695771
5303108.259088,,840.845621204304,15.1984766882557,0,15.8468152616441,15.8468152616441
5303108.427024,,841.20487609582,15.1911962670829,0,15.837138492555,15.837138492555
5303108.59496,,841.543693426146,15.1843364646363,0,15.8278248078407,15.8278248078407
5303108.762896,,841.862186632254,15.17789384807,0,15.8188605841251,15.8188605841251
5303108.930832,,842.16186820711,15.1718367968931,0,15.8102327091984,15.8102327091984
5303109.098768,,842.443607834169,15.166146829436,0,15.8019285628368,15.8019285628368
5303109.266704,,842.71052503017,15.1607601856177,0,15.7939359983433,15.7939359983433
5303109.43464,,842.952618435383,15.1558778488433,0,15.7862433247798,15.7862433247798
5303109.602576,,843.189966393919,15.1510942950612,0,15.7788392898668,15.7788392898668
5303109.770512,,843.406631011158,15.1467302579957,0,15.7717130635242,15.7717130635242
5303109.938448,,843.611611620241,15.142603895116,0,15.76485422203,15.76485422203
5303110.106384,,843.799898088224,15.1388155935998,0,15.7582527327731,15.7582527327731
5303110.27432,,843.981472868674,15.1351641429967,0,15.7518989395786,15.7518989395786
5303110.442256,,844.151685045725,15.131742808236,0,15.7457835485829,15.7457835485829
5303110.610192,,844.306469794532,15.1286329270939,0,15.7398976146401,15.7398976146401
5303110.778128,,844.454032389432,15.1256693528613,0,15.7342325282369,15.7342325282369
5303110.946064,,844.595318138526,15.1228329385123,0,15.7287800028999,15.7287800028999
5303111.114,,844.723085981746,15.1202688310874,0,15.7235320630742,15.7235320630742
5303111.281936,,844.848698522491,15.1177488334397,0,15.7184810324579,15.7184810324579
5303111.449872,,844.962551430433,15.1154654867187,0,15.7136195227733,15.7136195227733
5303111.617808,,845.074551534492,15.1132199782272,0,15.7089404229599,15.7089404229599
5303111.785744,,845.171313271929,15.1112805289148,0,15.7044368887733,15.7044368887733
5303111.95368,,845.267072982777,15.1093616588587,0,15.7001023327734,15.7001023327734
5303112.121616,,845.359524115263,15.107509554484,0,15.6959304146892,15.6959304146892
5303352.03,BEGIN:PULSE:PARAMS
5303352.03,ThResSigmaPerCycle=0.0220248344562925
5303352.03,TempSigmaPerCycle=0.000465143828961345
5303352.03,NBinsOn=128
5303352.03,NBinsOff=128
5303352.03,Period=30.7387855836698
5303352.03,Iterations=1
5303352.03,HtrOverLoad=0
5303352.03,NCycRec=28
5303352.03,ThFreqHz=244.140625
5303352.03,NSampPerBin=28
5303352.03,PPMSTemp=15.0009
5303352.03,EstTau=4.3912550833814
5303352.03,ThermOverload=0
5303352.03,ThResCorrFact=1
5303352.03,AvgHtrOnResistance=1194.29848961333
5303352.03,IsAddenda=0
5303352.03,AddendafromTbl=5.01689326964567E-5
5303352.03,AddendafromTblMinMidMax=1.98714849998986E-5|4.73879001997927E-5|8.6148222360798E-5
5303352.03,AddendaOffsetMinMidMax=0|0|0
5303352.03,AddendaErrfromTbl=1.8865312440715E-7
5303352.03,CondfromTbl=1.7717121809074E-5
5303352.03,TempMinMidMax=15.2653276868243|21.0702424840346|26.8751572812449
5303352.03,CondfromTblMinMidMax=1.79654916381204E-5|2.50511554630309E-5|3.11990800716654E-5
5303352.03,DisableTau2Fitting=1
5303352.03,HtrCurrOn=0.000477458755358642
5303352.03,StableStartTemperature=15.0819079652807
5303352.03,TimeStamp=5303352.03
5303352.03,PPMSStatus=5905
5303352.03,PuckTemp=
5303352.03,SystemTemp=15.0009
5303352.03,Field=-0.178
5303352.03,Pressure=9.41E-5
5303352.03,SampleTemp=21.342991
5303352.03,TempRise=11.421797
5303352.03,SampHC=5882.3277
5303352.03,SampHCErr=703.2
5303352.03,AddendaHC=50.168933
5303352.03,AddendaHCErr=0.1887
5303352.03,TotalHC=95.043651
5303352.03,TotalHCErr=3.842
5303352.03,FitDeviation=27526580
5303352.03,TimeConsttau1=4.1549374
5303352.03,TimeConsttau2=
5303352.03,SampleCoupling=
5303352.03,DebyeTemp=233.07307
5303352.03,DebyeTempErr=13.35
5303352.03,CalCorrection=1
5303352.03,ThermCondWire=2.287487E-5
5303352.03,AddendaOffset=0
5303352.03,END:PULSE:PARAMS
5303352.148784,,825.695841629477,15.5119002593974,0.000276094498706997,15.806496969385,15.806496969385
5303352.267568,,794.950928812634,16.1897100018539,0.000275665930549717,16.1371686995567,16.1371686995567
5303352.386352,,770.899729218978,16.7628312961995,0.000275336809147166,16.4585208274755,16.4585208274755
5303352.505136,,751.163350661651,17.2643878156322,0.000275057411121978,16.7708160154078,16.7708160154078
5303352.62392,,734.522745936454,17.7111890629453,0.000274832472033903,17.0743095227865,17.0743095227865
5303352.742704,,720.238589490219,18.1135542597787,0.000274614636285451,17.3692494148511,17.3692494148511
5303352.861488,,707.789350803779,18.4794022980193,0.000274463098373485,17.6558767654077,17.6558767654077
5303352.980272,,696.800775687385,18.8147814020635,0.000274302089342021,17.9344258538744,17.9344258538744
5303353.099056,,687.021497774288,19.1236099575061,0.000274141080310556,18.2051243567737,18.2051243567737
5303353.21784,,678.258569678217,19.4090364744534,0.000274010852417461,18.4681935338271,18.4681935338271
5303353.336624,,670.330279471001,19.6746738285432,0.000273897198983486,18.7238484088055,18.7238484088055
5303353.455408,,663.131240716298,19.9222125265838,0.000273804855568381,18.9722979452821,18.9722979452821
5303353.574192,,656.566222103357,20.1534032278427,0.000273707776593528,19.2137452174323,19.2137452174323
5303353.692976,,650.527730547441,20.37080271798,0.000273610697618674,19.4483875760197,19.4483875760197
5303353.81176,,644.971742498771,20.5749803064665,0.000273532560882817,19.6764168097033,19.6764168097033
5303353.930544,,639.842350749957,20.7671157338212,0.000273456791926834,19.8980193017998,19.8980193017998
5303354.049328,,635.0728177602,20.9489890900586,0.000273395229650097,20.1133761826264,20.1133761826264
5303354.168112,,630.631165687205,21.1212195174328,0.000273340770712984,20.3226634775506,20.3226634775506
5303354.286896,,626.492870982997,21.2842288559959,0.000273279208436248,20.5260522508676,20.5260522508676
5303354.40568,,622.605996662162,21.4396184913674,0.000273212910599763,20.7237087456222,20.7237087456222
5303354.524464,,618.935269868249,21.5884417110313,0.000273163187222399,20.9157945194903,20.9157945194903
5303354.643248,,615.463270239538,21.7311002953484,0.00027311583162491,21.1024665768307,21.1024665768307
5303354.762032,,612.137574640983,21.8695060938662,0.000273073211587169,21.2838774970146,21.2838774970146
5303354.880816,,608.892741930797,22.0062361762351,0.00027302585598968,21.4601755591397,21.4601755591397
5303354.9996,,605.713809503715,22.1418372318116,0.000272969029272692,21.6315048632274,21.6315048632274
5303355.118384,,602.561210181564,22.2779548588537,0.00027293588035445,21.7980054480063,21.7980054480063
5303355.237168,,599.443991749112,22.4141792711599,0.000272893260316709,21.9598134053742,21.9598134053742
5303355.355952,,596.411012244121,22.5483099500378,0.000272848272499094,22.1170609916355,22.1170609916355
5303355.474736,,593.467619312517,22.6800019628271,0.000272796181341856,22.2698767356028,22.2698767356028
5303355.59352,,590.620484007546,22.808839108433,0.000272760664643738,22.4183855436521,22.4183855436521
5303355.712304,,587.882192202951,22.934120048469,0.000272720412385872,22.5627088018166,22.5627088018166
5303355.831088,,585.259549993543,23.0553885379925,0.000272675424568258,22.7029644750042,22.7029644750042
5303355.949872,,582.725981199578,23.1737447752715,0.000272656482329262,22.8392672034173,22.8392672034173
5303356.068656,,580.296421418007,23.2883723575282,0.000272616230071396,22.9717283962563,22.9717283962563
5303356.18744,,577.977811785205,23.398811903852,0.000272578345593404,23.1004563227814,23.1004563227814
5303356.306224,,575.731827505382,23.5067803198197,0.000272535725555664,23.2255562008082,23.2255562008082
5303356.425008,,573.58982522964,23.6106681461022,0.000272516783316668,23.3471302827093,23.3471302827093
5303356.543792,,571.530441382595,23.7114048855493,0.0002724860021783,23.4652779389919,23.4652779389919
5303356.662576,,569.545384412232,23.8093099131682,0.000272455221039931,23.5800957395196,23.5800957395196
5303356.78136,,567.637490191391,23.904161948284,0.000272429175461312,23.6916775324457,23.6916775324457
5303356.900144,,565.813618831509,23.9955344964797,0.000272419704341814,23.8001145209211,23.8001145209211
5303357.018928,,564.050327117122,24.084527766194,0.000272384187643697,23.9054953376409,23.9054953376409
5303357.137712,,562.352368511272,24.1708394036772,0.000272362877624827,24.0079061172898,24.0079061172898
5303357.256496,,560.727818499471,24.253990838989,0.000272353406505329,24.1074305669454,24.1074305669454
5303357.37528,,559.157852287735,24.3348846231152,0.000272308418687714,24.2041500344975,24.2041500344975
5303357.494064,,557.633827215983,24.4139202353894,0.000272298947568216,24.2981435751395,24.2981435751395
5303357.612848,,556.183858937786,24.4895850888772,0.000272277637549346,24.3894880159848,24.3894880159848
5303357.731632,,554.780398974142,24.5632631993247,0.000272263430870099,24.4782580188634,24.4782580188634
5303357.850416,,553.417235413118,24.6352440473437,0.000272242120851229,24.5645261413471,24.5645261413471
5303357.9692,,552.109384876602,24.7046947595637,0.000272218443052484,24.6483628960564,24.6483628960564
5303358.087984,,550.851661768547,24.7718473242709,0.000272194765253739,24.7298368082945,24.7298368082945
5303358.206768,,549.626861793732,24.8375875294033,0.00027219002969399,24.8090144720579,24.8090144720579
5303358.325552,,548.45497110359,24.9008094239821,0.000272156880775748,24.8859606044677,24.8859606044677
5303358.444336,,547.321675292365,24.9622504749475,0.000272149777436124,24.9607380986677,24.9607380986677
5303358.56312,,546.214631561132,25.0225563637064,0.000272140306316626,25.0334080752305,25.0334080752305
5303358.681904,,545.153096836879,25.0806524037486,0.000272114260738007,25.1040299321161,25.1040299321161
5303358.800688,,544.132155606687,25.1367771595675,0.000272107157398384,25.1726613932209,25.1726613932209
5303358.919472,,543.132334877064,25.1919802771554,0.000272088215159388,25.23935855556,25.23935855556
5303359.038256,,542.175376339772,25.2450401476909,0.000272083479599639,25.3041759351185,25.3041759351185
5303359.15704,,541.248829162634,25.2966231981443,0.00027205743402102,25.3671665114112,25.3671665114112
5303359.275824,,540.345617167711,25.347106575748,0.000272059801800894,25.4283817707863,25.4283817707863
5303359.394608,,539.471628167181,25.3961451168761,0.000272040859561899,25.4878717485086,25.4878717485086
5303359.513392,,538.634829613306,25.4432716698134,0.000272024285102777,25.5456850696563,25.5456850696563
5303359.632176,,537.812615548314,25.4897442402799,0.000272021917322903,25.6018689888659,25.6018689888659
5303359.75096,,537.022244284053,25.5345742288416,0.000272019549543028,25.6564694289563,25.6564694289563
5303359.869744,,536.264012911961,25.5777268061979,0.000271991136184535,25.7095310184644,25.7095310184644
5303359.988528,,535.517098022911,25.6203753941185,0.000271984032844911,25.7610971281236,25.7610971281236
5303360.107312,,534.793005158134,25.6618541821651,0.000271972193945539,25.8112099063125,25.8112099063125
5303360.226096,,534.101349276967,25.7015979977563,0.000271965090605915,25.8599103135065,25.8599103135065
5303360.34488,,533.424493951186,25.7406083546193,0.000271950883926669,25.9072381557572,25.9072381557572
5303360.463664,,532.762412172478,25.7788797120579,0.000271953251706543,25.9532321172282,25.9532321172282
5303360.582448,,532.134063776393,25.8153044332413,0.000271936677247422,25.9979297918145,25.9979297918145
5303360.701232,,531.514601115201,25.8513129455714,0.000271922470568175,26.0413677138705,26.0413677138705
5303360.820016,,530.909452859766,25.8865845670684,0.000271924838348049,26.0835813880718,26.0835813880718
5303360.9388,,530.336066380124,25.9200920578121,0.000271910631668803,26.1246053184357,26.1246053184357
5303361.057584,,529.771727685251,25.9531539160583,0.000271912999448677,26.1644730365233,26.1644730365233
5303361.176368,,529.215680542393,25.9858109401845,0.000271901160549305,26.2032171288472,26.2032171288472
5303361.295152,,528.688505285862,26.0168467442129,0.000271891689429807,26.240869263507,26.240869263507
5303361.413936,,528.17920953237,26.0468990021045,0.000271886953870058,26.2774602160729,26.2774602160729
5303361.53272,,527.665619457151,26.0772736118578,0.000271891689429807,26.3130198947412,26.3130198947412
5303361.651504,,527.185141573362,26.1057528055305,0.000271884586090183,26.3475773647803,26.3475773647803
5303361.770288,,526.714899840104,26.1336843352294,0.000271868011631062,26.3811608722872,26.3811608722872
5303361.889072,,526.244523065283,26.1616825159797,0.00027185617273169,26.4137978672753,26.4137978672753
5303362.007856,,525.806340199257,26.1878173365504,0.000271858540511564,26.4455150261109,26.4455150261109
5303362.12664,,525.374720353229,26.2136107586672,0.000271849069392066,26.4763382733176,26.4763382733176
5303362.245424,,524.946638596171,26.2392419423475,0.000271832494932945,26.5062928027662,26.5062928027662
5303362.364208,,524.537948807666,26.2637578831374,0.000271839598272568,26.5354030982671,26.5354030982671
5303362.482992,,524.143222316852,26.2874788371197,0.000271818288253698,26.5636929535829,26.5636929535829
5303362.601776,,523.748387792787,26.311248294522,0.000271825391593321,26.5911854918761,26.5911854918761
5303362.72056,,523.378616982952,26.333547087252,0.000271818288253698,26.6179031846096,26.6179031846096
5303362.839344,,523.013950744227,26.3555743255169,0.000271804081574451,26.6438678699142,26.6438678699142
5303362.958128,,522.649338522127,26.3776344010857,0.0002718088171342,26.6691007704377,26.6691007704377
5303363.076912,,522.311437521335,26.3981106749265,0.000271799346014702,26.6936225106922,26.6936225106922
5303363.195696,,521.977668792394,26.4183671160728,0.000271799346014702,26.7174531339117,26.7174531339117
5303363.31448,,521.640902140737,26.4388363686205,0.000271799346014702,26.7406121184346,26.7406121184346
5303363.433264,,521.324580781831,26.4580912215501,0.000271801713794577,26.7631183936248,26.7631183936248
5303363.552048,,521.018711639958,26.476735961194,0.000271785139335455,26.7849903553439,26.7849903553439
5303363.670832,,520.712113273641,26.4954509830818,0.000271782771555581,26.8062458809872,26.8062458809872
5303363.789616,,520.4164802823,26.513521209348,0.000271799346014702,26.8269023440963,26.8269023440963
5303363.9084,,520.141778733339,26.5303336618978,0.000271780403775707,26.8469766285594,26.8469766285594
5303364.027184,,519.856949067097,26.547788032577,0.00027176619709646,26.8664851424119,26.8664851424119
5303364.145968,,519.581437268754,26.56469280379,0.00027176619709646,26.8854438312474,26.8854438312474
5303364.264752,,519.325209405712,26.5804332771296,0.000271754358197087,26.9038681912514,26.9038681912514
5303364.383536,,519.063660905059,26.5965194442456,0.000271763829316585,26.9217732818673,26.9217732818673
5303364.50232,,518.812780687942,26.611967387938,0.000271751990417213,26.9391737381052,26.9391737381052
5303364.621104,,518.577025125963,26.6265000445844,0.000271761461536711,26.9560837825046,26.9560837825046
5303364.739888,,518.33532773518,26.6414151057972,0.000271744887077589,26.9725172367588,26.9725172367588
5303364.858672,,518.102840179044,26.6557772676027,0.000271751990417213,26.9884875330128,26.9884875330128
5303364.977456,,517.892472431049,26.6687860196543,0.000271749622637338,27.0040077248418,27.0040077248418
5303365.09624,,517.664468254829,26.6828994130489,0.000271744887077589,27.0190904979213,27.0190904979213
5303365.215024,,517.447267403708,26.696357684032,0.000271744887077589,27.0337481803953,27.0337481803953
5303365.333808,,517.248810321635,26.7086661658895,0.000271737783737966,27.0479927529535,27.0479927529535
[...]
5311704.932288,,142.497198557986,111.818326298952,0.00204064808669782,111.559811015351,111.559811015351
5311705.681856,,142.267256852655,112.014158985102,0.00204072611618232,111.773909265965,111.773909265965
5311706.431424,,142.044470868445,112.204511165182,0.00204077913621666,111.982243576544,111.982243576544
5311707.180992,,141.829436846343,112.38881545363,0.00204084416078708,112.184969123531,112.184969123531
5311707.93056,,141.620524452857,112.568416759097,0.00204091018573551,112.382236905716,112.382236905716
5311708.680128,,141.418657488347,112.74247249249,0.0020409702084159,112.574193856709,112.574193856709
5311709.429696,,141.222591227191,112.912009834239,0.00204104023487635,112.760982954385,112.760982954385
5311710.179264,,141.032786740307,113.076588037683,0.0020411092609588,112.942743327374,112.942743327374
5311710.928832,,140.848651933026,113.236679905207,0.00204115527834709,113.119610358696,113.119610358696
5311711.6784,,140.669980318554,113.392428107253,0.0020412173017835,113.291715786597,113.291715786597
5311712.427968,,140.497057163789,113.543547754308,0.00204127532370787,113.459187802673,113.459187802673
5311713.177536,,140.329051545963,113.690731442692,0.00204132934412022,113.622151147354,113.622151147354
5311713.927104,,140.166266975788,113.83368223158,0.00204136635810646,113.780727202817,113.780727202817
5311714.676672,,140.00817272415,113.972836585917,0.00204142738116485,113.935034083394,113.935034083394
5311715.42624,,139.85458884071,114.108326157596,0.00204147239817514,114.08518672355,114.08518672355
5311716.175808,,139.706017859596,114.239680586592,0.00204151741518544,114.231296963493,114.231296963493
5311716.925376,,139.561382566562,114.367827527318,0.00204155943106171,114.373473632475,114.373473632475
5311717.674944,,139.420662230002,114.492764268207,0.00204159144315791,114.511822629853,114.511822629853
5311718.424512,,139.284951478711,114.613495480472,0.0020416504654603,114.646447003968,114.646447003968
5311719.17408,,139.152354614639,114.731686825415,0.00204169348171457,114.777447028901,114.777447028901
5311719.923648,,139.023643682793,114.846632747932,0.00204172149229876,114.904920279158,114.904920279158
5311720.673216,,138.898982877491,114.958167282961,0.00204176550893104,115.028961702353,115.028961702353
5311721.422784,,138.777316545357,115.067218243105,0.00204180452367329,115.149663689923,115.149663689923
5311722.172352,,138.659656388763,115.17286266656,0.00204185654332963,115.267116145952,115.267116145952
5311722.92192,,138.544727828574,115.276229786736,0.00204189455769387,115.381406554129,115.381406554129
5311723.671488,,138.433250666148,115.376658657984,0.00204192056752204,115.492620042913,115.492620042913
5311724.421056,,138.325332705838,115.474037115124,0.00204196858566635,115.60083944894,115.60083944894
5311725.170624,,138.219743319512,115.569463329348,0.0020420216057007,115.706145378723,115.706145378723
5311725.920192,,138.117480112049,115.662024233996,0.00204204661515086,115.808616268693,115.808616268693
5311726.66976,,138.017610161181,115.752552877419,0.00204206662271099,115.908328443618,115.908328443618
5311727.419328,,137.920549757556,115.840661846115,0.00204210263631922,116.005356173455,116.005356173455
5311728.168896,,137.826215145486,115.926416698597,0.00204212964652539,116.099771728672,116.099771728672
5311728.918464,,137.734367496869,116.010024932413,0.00204216866126765,116.191645434075,116.191645434075
5311729.668032,,137.6452365179,116.091268093317,0.00204219967298585,116.281045721189,116.281045721189
5311730.4176,,137.558686209244,116.170260858294,0.00204223268546006,116.36803917923,116.36803917923
5311731.167168,,137.474288670553,116.247385691621,0.00204226069604424,116.452690604703,116.452690604703
5311731.916736,,137.39210692591,116.322577740715,0.0020422857054944,116.535063049667,116.535063049667
5311732.666304,,137.312296047726,116.39568767331,0.00204231771759061,116.615217868696,116.615217868696
5311733.415872,,137.234088966582,116.467411864847,0.00204233472401672,116.693214764579,116.693214764579
5311734.16544,,137.158571189365,116.536748153694,0.00204235773271087,116.769111832792,116.769111832792
5311734.915008,,137.084980622241,116.604389278324,0.00204239974858714,116.842965604767,116.842965604767
5311735.664576,,137.01352872759,116.670134909958,0.00204241475425724,116.914831090001,116.914831090001
5311736.414144,,136.943685605563,116.734467270956,0.00204243276106135,116.984761817028,116.984761817028
5311737.163712,,136.875804522726,116.797055989532,0.0020424707754256,117.05280987329,117.05280987329
5311737.91328,,136.809602699974,116.858156834578,0.00204249678525377,117.119025943936,117.119025943936
5311738.662848,,136.74515311256,116.917697894109,0.00204250078676579,117.183459349569,117.183459349569
5311739.412416,,136.682263371179,116.975852607486,0.0020425488049101,117.246158082988,117.246158082988
5311740.161984,,136.620809915461,117.032731438445,0.00204256080944618,117.307168844934,117.307168844934
5311740.911552,,136.561512546766,117.08766371974,0.00204258281776232,117.36653707887,117.36653707887
5311741.66112,,136.503376977269,117.141566540837,0.00204258481851834,117.424307004836,117.424307004836
5311742.410688,,136.446885009495,117.193989887457,0.00204261382948052,117.480521652382,117.480521652382
5311743.160256,,136.39208888709,117.244881444546,0.00204262783477261,117.535222892617,117.535222892617
5311743.909824,,136.338599685127,117.294599069204,0.00204266284800284,117.588451469402,117.588451469402
5311744.659392,,136.286086527173,117.343447824884,0.00204267285178291,117.640247029692,117.640247029692
5311745.40896,,136.234995557389,117.391010144681,0.00204269085858702,117.690648153069,117.690648153069
5311746.158528,,136.185537408893,117.437086755063,0.00204271486765918,117.739692380479,117.739692380479
5311746.908096,,136.137436765956,117.481931112832,0.00204272587181725,117.787416242192,117.787416242192
5311747.657664,,136.090099875384,117.526094683288,0.00204275188164542,117.833855285013,117.833855285013
5311748.407232,,136.044419025498,117.568742661064,0.00204276588693751,117.879044098758,117.879044098758
5311749.1568,,135.999602268949,117.610612035608,0.00204278189298561,117.923016342017,117.923016342017
5311749.906368,,135.955988774811,117.651384046615,0.00204278889563166,117.965804767227,117.965804767227
5311750.655936,,135.913721176534,117.690923064692,0.00204280590205777,118.007441245066,118.007441245066
5311751.405504,,135.872450353872,117.7295536252,0.00204282791037391,118.04795678819,118.04795678819
5311752.155072,,135.831949917689,117.767486130595,0.00204282891075191,118.087381574334,118.087381574334
5311752.90464,,135.792938840079,117.804045314468,0.00204285191944606,118.125744968793,118.125744968793
5311753.654208,,135.754195614819,117.840374480297,0.00204285492058008,118.163075546288,118.163075546288
5311754.403776,,135.716871260672,117.875392991561,0.00204286892587217,118.199401112253,118.199401112253
5311755.153344,,135.68025592745,117.909765187342,0.00204287492814021,118.23474872355,118.23474872355
5311755.902912,,135.644886978379,117.942985145978,0.00204289393532233,118.269144708612,118.269144708612
5311756.65248,,135.610140806753,117.975637203281,0.00204291394288246,118.302614687064,118.302614687064
5311757.402048,,135.576456093352,118.007307906707,0.00204291394288246,118.335183588799,118.335183588799
5311758.151616,,135.543442254721,118.038363268062,0.00204293795195462,118.36687567255,118.36687567255
5311758.901184,,135.511705483019,118.068231723554,0.00204295996027076,118.397714543956,118.397714543956
5311759.650752,,135.480431440762,118.097678509998,0.00204296196102677,118.427723173149,118.427723173149
5311760.40032,,135.449985004216,118.126359232945,0.00204297496594086,118.456923911858,118.456923911858
5311761.149888,,135.420368661173,118.154270494495,0.00204297796707488,118.485338510062,118.485338510062
5311761.899456,,135.391038414293,118.181924279887,0.00204299197236697,118.512988132188,118.512988132188
5311762.649024,,135.362655187175,118.208696693166,0.00204300297652504,118.539893372874,118.539893372874
5311763.398592,,135.335170882491,118.234632002808,0.00204300797841507,118.566074272313,118.566074272313
5311764.14816,,135.308696621652,118.259624250164,0.00204303098710922,118.591550331175,118.591550331175
5311764.897728,,135.282040751943,118.284797915551,0.00204301898257314,118.616340525136,118.616340525136
5311765.647296,,135.256679363713,118.308758376841,0.00204303098710922,118.640463319008,118.640463319008
5311766.396864,,135.231452316289,118.332600917323,0.00204304799353533,118.663936680495,118.663936680495
5311767.146432,,135.207329019568,118.355408682333,0.0020430589976934,118.686778093578,118.686778093578
5311767.896,,135.183706598447,118.37775084801,0.00204306800109546,118.709004571532,118.709004571532
5311768.645568,,135.160267444723,118.399927469458,0.0020430750037415,118.730632669603,118.730632669603
5311769.395136,,135.137774481496,118.42121616666,0.00204308400714356,118.751678497338,118.751678497338
5311770.144704,,135.116091709431,118.441744821711,0.00204307800487552,118.772157730583,118.772157730583
5311770.894272,,135.389342568924,118.18352356382,0,118.46552892924,118.46552892924
5311771.64384,,135.947037696612,117.659755216572,0,117.847088954121,117.847088954121
5311772.393408,,136.493148832142,117.151054791933,0,117.245298582263,117.245298582263
5311773.142976,,137.033458435053,116.651789851596,0,116.659709574063,116.659709574063
5311773.892544,,137.568198699333,116.161574079105,0,116.089885757399,116.089885757399
5311774.642112,,138.098392107789,115.679316608114,0,115.535402702746,115.535402702746
5311775.39168,,138.623104908887,115.205718374968,0,114.995847407046,114.995847407046
5311776.141248,,139.142710271536,114.740292290891,0,114.470817986083,114.470817986083
5311776.890816,,139.657141854596,114.282954676451,0,113.959923375143,113.959923375143
5311777.640384,,140.166903021459,113.833123027387,0,113.462783037736,113.462783037736
5311778.389952,,140.671060849858,113.391485001756,0,112.979026682147,112.979026682147
5311779.13952,,141.169453633265,112.958039856011,0,112.508293985636,112.508293985636
5311779.889088,,141.662274590249,112.532481336106,0,112.050234326047,112.050234326047
5311780.638656,,142.149553574321,112.114651248821,0,111.604506520655,111.604506520655
5311781.388224,,142.631191903037,111.704504765201,0,111.170778572033,111.170778572033
5311782.137792,,143.106529482063,111.302471482569,0,110.748727420769,110.748727420769
5311782.88736,,143.576453624135,110.90767373321,0,110.338038704839,110.338038704839
5311783.636928,,144.04042779529,110.520435665278,0,109.93840652545,109.93840652545
5311784.386496,,144.498129411738,110.140899734878,0,109.549533219203,109.549533219203
5311785.136064,,144.95005520276,109.768534660716,0,109.17112913637,109.17112913637
5311785.885632,,145.395149514979,109.404089926995,0,108.802912425158,108.802912425158
5311786.6352,,145.834820439073,109.04629825945,0,108.444608821769,108.444608821769
5311787.384768,,146.26768476229,108.696174425699,0,108.095951446121,108.095951446121
5311788.134336,,146.694170384979,108.353257620062,0,107.756680603058,107.756680603058
5311788.883904,,147.115123156663,108.016765315632,0,107.426543588924,107.426543588924
5311789.633472,,147.529102645358,107.68774530974,0,107.105294503333,107.105294503333
5311790.38304,,147.936701774997,107.365619907545,0,106.792694066016,106.792694066016
5311791.132608,,148.337801960792,107.050382611931,0,106.488509438592,106.488509438592
5311791.882176,,148.73310476029,106.741388412323,0,106.19251405114,106.19251405114
5311792.631744,,149.121198765756,106.439645163659,0,105.904487433442,105.904487433442
5311793.381312,,149.503147093944,106.144231463853,0,105.624215050765,105.624215050765
5311794.13088,,149.878428137648,105.855461964335,0,105.351488144067,105.351488144067
5311794.880448,,150.247553552904,105.572856645436,0,105.086103574505,105.086103574505
5311795.630016,,150.609675002395,105.29697930584,0,104.827863672125,104.827863672125
5311796.379584,,150.96569804267,105.027057150402,0,104.576576088635,104.576576088635
5311797.129152,,151.314911165012,104.763550226097,0,104.332053654129,104.332053654129
5311797.87872,,151.65783265957,104.505989330507,0,104.09411423768,104.09411423768
5311798.628288,,151.994258527342,104.254453503814,0,103.862580611677,103.862580611677
5311799.377856,,152.323589210282,104.009315019506,0,103.63728031982,103.63728031982
5311800.127424,,152.646504705067,103.769994406267,0,103.418045548669,103.418045548669
5311800.876992,,152.961496580046,103.537534685305,0,103.204713002646,103.204713002646
5311801.62656,,153.266840794864,103.31312093614,0,102.997123782404,102.997123782404
5311802.376128,,153.554381535729,103.10262054588,0,102.79512326648,102.79512326648
5311803.125696,,153.813350806493,102.913720650626,0,102.598560996115,102.598560996115
5311803.875264,,154.068198633987,102.728456757162,0,102.407290563195,102.407290563195
5311804.624832,,154.330646668235,102.538317427654,0,102.221169501195,102.221169501195
5311805.3744,,154.595804738016,102.346880741994,0,102.040059179066,102.040059179066
5311806.123968,,154.86094953957,102.156119618087,0,101.863824697974,101.863824697974
5311806.873536,,155.123291427995,101.96802718953,0,101.692334790825,101.692334790825
5311807.623104,,155.381633774994,101.783433028265,0,101.525461724489,101.525461724489
5311808.372672,,155.635424290583,101.6026976941,0,101.36308120466,101.36308120466
5311809.12224,,155.884482195159,101.425914117113,0,101.205072283273,101.205072283273
5311809.871808,,156.128505636538,101.253260027341,0,101.051317268424,101.051317268424
5311810.621376,,156.367559297331,101.084653329348,0,100.901701636699,100.901701636699
5311811.370944,,156.601414300607,100.920219606297,0,100.75611394788,100.75611394788
5311812.120512,,156.830675179998,100.759500137227,0,100.614445761932,100.614445761932
5311812.87008,,157.054598914744,100.602982691601,0,100.476591558239,100.476591558239
5311813.619648,,157.274257743508,100.449886598368,0,100.342448657004,100.342448657004
5311814.369216,,157.488667329637,100.300867875925,0,100.211917142768,100.211917142768
5311815.118784,,157.698283768463,100.155578816494,0,100.08489978999,100.08489978999
5311815.868352,,157.903199108316,100.013927349183,0,99.9613019906315,99.9613019906315
5311816.61792,,158.103730128136,99.8756690410787,0,99.8410316836827,99.8410316836827
5311817.367488,,158.299497024901,99.7410409924753,0,99.7239992865965,99.7239992865965
5311818.117056,,158.490802480059,99.6098095369046,0,99.6101176285612,99.6101176285612
5311818.866624,,158.677552786751,99.4820147881896,0,99.4993018855723,99.4993018855723
5311819.616192,,158.859656725909,99.3576952694671,0,99.3914695172522,99.3914695172522
5311820.36576,,159.037480832328,99.2365782331683,0,99.28654020537,99.28654020537
5311821.115328,,159.211414030937,99.1183786840326,0,99.1844357940176,99.1844357940176
5311821.864896,,159.380792910343,99.0035273315452,0,99.0850802313953,99.0850802313953
5311822.614464,,159.546104248656,98.8916741841246,0,98.9883995131655,98.9883995131655
5311823.364032,,159.70734721661,98.7828015315656,0,98.8943216273305,98.8943216273305
5311824.1136,,159.864599765045,98.6768391739046,0,98.8027765005957,98.8027765005957
5311824.863168,,160.017822089277,98.5737969731632,0,98.713695946175,98.713695946175
5311825.612736,,160.167171749512,98.4735527548622,0,98.6270136130031,98.6270136130031
5311826.362304,,160.313102353287,98.3757874902711,0,98.5426649363139,98.5426649363139
5311827.111872,,160.455268926681,98.2807183590766,0,98.46058708955,98.46058708955
5311827.86144,,160.593699664677,98.1883124115788,0,98.3807189375667,98.3807189375667
5311828.611008,,160.728819979829,98.0982727988857,0,98.3030009910961,98.3030009910961
5311829.360576,,160.860393531829,98.0107448437696,0,98.2273753624367,98.2273753624367
5311830.110144,,160.987819933369,97.92611477425,0,98.1537857223359,98.1537857223359
5311830.859712,,161.112866346543,97.8431980323943,0,98.0821772580341,98.0821772580341
5311831.60928,,161.233878389191,97.763081241833,0,98.0124966324373,98.0124966324373
5311832.358848,,161.352626540467,97.6845823260076,0,97.9446919443897,97.9446919443897
5311833.108416,,161.467448954834,97.608790413476,0,97.878712690015,97.878712690015
5311833.857984,,161.579616065106,97.534857182725,0,97.8145097250993,97.8145097250993
5311834.607552,,161.688747238999,97.4630253362985,0,97.7520352284862,97.7520352284862
5311835.35712,,161.794626867809,97.3934280438123,0,97.6912426664576,97.6912426664576
5311836.106688,,161.89836284856,97.3253297412854,0,97.6320867580732,97.6320867580732
5311836.856256,,161.998846454965,97.2594511678008,0,97.5745234414435,97.5745234414435
5311837.605824,,162.096767634871,97.1953325732176,0,97.5185098409106,97.5185098409106
5311838.355392,,162.191662000303,97.1332711407203,0,97.4640042351123,97.4640042351123
5311839.10496,,162.284405254298,97.0726879434212,0,97.4109660259063,97.4109660259063
5311839.854528,,162.374257693155,97.0140603190706,0,97.3593557081311,97.3593557081311
5311840.604096,,162.461895167229,96.956941519842,0,97.3091348401809,97.3091348401809
5311841.353664,,162.547092116647,96.9014734538535,0,97.2602660153723,97.2602660153723
5311842.103232,,162.6299878578,96.8475603741136,0,97.2127128340823,97.2127128340823
5311842.8528,,162.710359318609,96.7953423886205,0,97.1664398766364,97.1664398766364
5311843.602368,,162.788869910465,96.7443840807406,0,97.1214126769263,97.1214126769263
5311844.351936,,162.865340512293,96.6947979087338,0,97.0775976967386,97.0775976967386
5311845.101504,,162.939112688286,96.647006362664,0,97.034962300773,97.034962300773
5311845.851072,,163.010742874748,96.6006445591971,0,96.9934747323352,96.9934747323352
5311846.60064,,163.080717849789,96.5553940741076,0,96.9531040896825,96.9531040896825
5311847.350208,,163.148928150529,96.5113227443874,0,96.9138203030072,96.9138203030072
5311848.099776,,163.214670560892,96.4688813976063,0,96.875594112039,96.875594112039
5311848.849344,,163.279154977405,96.4272859399298,0,96.8383970442506,96.8383970442506
5311849.598912,,163.341074479625,96.3873764029391,0,96.8022013936509,96.8022013936509
5311850.34848,,163.401518720764,96.3484473947899,0,96.7669802001473,96.7669802001473
5311851.098048,,163.460126141613,96.3107293398741,0,96.7327072294653,96.7327072294653
5311851.847616,,163.517543568278,96.2738037888611,0,96.6993569536081,96.6993569536081
5311852.597184,,163.572760956916,96.2383179572672,0,96.6669045318418,96.6669045318418
5311853.346752,,163.626474060224,96.2038222264648,0,96.6353257921935,96.6353257921935
5311854.09632,,163.678517854619,96.1704205153789,0,96.6045972134464,96.6045972134464
5311854.845888,,163.729839359861,96.1375035066158,0,96.5746959076208,96.5746959076208
5311855.595456,,163.778906095636,96.1060522873469,0,96.5455996029255,96.5455996029255
5311856.345024,,163.826780349435,96.0753838911029,0,96.5172866271692,96.5172866271692
5311857.094592,,163.873380853363,96.0455489542177,0,96.489735891618,96.489735891618
5311857.84416,,163.918355999382,96.0167709648812,0,96.4629268752877,96.4629268752877
5311858.593728,,163.96221412647,95.9887231672516,0,96.4368396096586,96.4368396096586
5311859.343296,,164.004728845491,95.9615490457977,0,96.4114546638025,96.4114546638025
5311860.092864,,164.046350446926,95.9349596426167,0,96.3867531299092,96.3867531299092
5311860.842432,,164.086388982928,95.9093944938467,0,96.3627166092037,96.3627166092037
5311861.592,,164.125044306179,95.8847245695847,0,96.3393271982415,96.3393271982415
5311862.341568,,164.163375387112,95.8602732335301,0,96.3165674755735,96.3165674755735
5311863.091136,,164.20012091482,95.8368442079398,0,96.29442048877,96.29442048877
5311863.840704,,164.236119275448,95.8139019059107,0,96.2728697417934,96.2728697417934
5311864.590272,,164.27064735058,95.7919062369183,0,96.2518991827114,96.2518991827114
5311865.33984,,164.304240844914,95.7705149441409,0,96.2314931917411,96.2314931917411
5311866.089408,,164.336791954099,95.7497958845935,0,96.2116365696141,96.2116365696141